Workbook

Sheet Validación de productos
A1: SKU | B1: Nombre Archivo producción | C1: Naturaleza | D1: Cliente | E1: ¿El producto esta definido correctamente?
A2: {=_xlfn._xlws.FILTER(_xlfn.HSTACK(Tabla5[SKU],Tabla5[Nombre Archivo producción],Tabla5[Naturaleza],Tabla5[Cliente]),Tabla5[Nombre Archivo producción]<>"")} -> 010103010101 | B2: P. Entero ST 48% | C2: Servicio Terceros | D2: Nestlé | E2: FALSE
A3: 010104010201 | B3: LEP NESTLÉ | C3: Servicio Terceros | D3: Nestlé | E3: FALSE
A4: 010210010201 | B4: LEP COLUN | C4: Servicio Terceros | D4: Colun | E4: FALSE
A5: 020003020101 | B5: P. Descremado ST 45% | C5: Producto Propio | D5: Cliente no definido | E5: FALSE
A6: 010104010101 | B6: Crema 42% NESTLÉ | C6: Servicio Terceros | D6: Nestlé | E6: FALSE
A7: 020004010101 | B7: Crema 42% CCAA | C7: Producto Propio | D7: Cliente no definido | E7: FALSE
A8: 020005050301 | B8: Mantequilla sin Sal | C8: Producto Propio | D8: Cliente no definido | E8: FALSE
A9: 010302010201 | B9: LEP | C9: Servicio Terceros | D9: Soprole | E9: FALSE
A10: 010302010201 | B10: LEP c/Lec | C10: Servicio Terceros | D10: Soprole | E10: FALSE
A11: 010302030201 | B11: Leche Descremada en Polvo | C11: Servicio Terceros | D11: Soprole | E11: FALSE
A12: 010302030201 | B12: Leche Descremada en Polvo C/Lec | C12: Servicio Terceros | D12: Soprole | E12: FALSE
A13: 010208030201 | B13: Suero en Polvo Colun | C13: Servicio Terceros | D13: Colun | E13: FALSE
A14: 020003020101 | B14: P. Semidescremado ST 45% CCAA | C14: Producto Propio | D14: Cliente no definido | E14: FALSE
... A17: 020012080101 | B17: Leche estandarizada | C17: Producto Propio | D17: Cliente no definido | E17: FALSE

Sheet Código de Producto
A1: Categoría | B1: Código | D1: Tipo | E1: Código | G1: Formato | H1: Código | J1: Naturaleza | K1: Código | M1: Mercado | N1: Código | P1: |
A2: Leche en Polvo | B2: 02 | D2: Entera | E2: 01 | G2: Granel | H2: 01 | J2: Servicio Terceros | K2: 01 | M2: Local | N2: 01 | P2: Naturaleza | Q2: Cliente | R2: Categoría | S2: Tipo | T2: Formato | U2: Peso kilos | V2: Cód. Naturaleza | W2: Cód. Categoría | X2: Cód. Tipo | Y2: Cód. Formato | Z2: Cód. Mercado | AA2: Cód. Cliente | AB2: SKU | AC2: Nombre | AD2: Cód. Patricio R. | AE2: Nombre Archivo producción | AF2: Cód. CeGe
A3: Pre condensados | B3: 03 | D3: Semidescremada | E3: 02 | G3: Saco 25kg | H3: 02 | J3: Producto Propio | K3: 02 | M3: Exportación | N3: 02 | P3: Servicio Terceros | Q3: Nestlé | R3: Pre condensados | S3: Entera | T3: Granel | V3: =_xlfn.XLOOKUP(Tabla5[[#This Row],[Naturaleza]],Tabla37[Naturaleza],Tabla37[Código]) -> 01 | W3: =_xlfn.XLOOKUP(Tabla5[[#This Row],[Categoría]],Tabla1[Categoría],Tabla1[Código],"",0,1) -> 03 | X3: =_xlfn.XLOOKUP(Tabla5[[#This Row],[Tipo]],Tabla2[Tipo],Tabla2[Código],"",0,1) -> 01 | Y3: =_xlfn.XLOOKUP(Tabla5[[#This Row],[Formato]],Tabla3[Formato],Tabla3[Código],"",0,1) -> 01 | Z3: =_xlfn.XLOOKUP("Local",Tabla4[Mercado],Tabla4[Código],"",0,1) -> 01 | AA3: =_xlfn.XLOOKUP(Tabla5[[#This Row],[Cliente]],Tabla6[Cliente],Tabla6[Código]) -> 01 | AB3: =Tabla5[[#This Row],[Cód. Naturaleza]]&Tabla5[[#This Row],[Cód. Cliente]]&Tabla5[[#This Row],[Cód. Categoría]]&Tabla5[[#This Row],[Cód. Tipo]]&Tabla5[[#This Row],[Cód. Formato]]&Tabla5[[#This Row],[Cód. Mercado]] -> 010103010101 | AC3: Precondensado Entero NE Granel | AD3: 5001 | AE3: =IFERROR(IF(_xlfn.XLOOKUP(TEXT(Tabla5[[#This Row],[Cód. Patricio R.]],"0"),Diccionario!A:A,Diccionario!C:C,"",0,1)=0,"",_xlfn.XLOOKUP(TEXT(Tabla5[[#This Row],[Cód. Patricio R.]],"0"),Diccionario!A:A,Diccionario!C:C,"",0,1)),"") -> P. Entero ST 48% | AF3: 101
A4: Crema | B4: 04 | D4: Descremada | E4: 03 | G4: Caja 20kg | H4: 03 | P4: Servicio Terceros | Q4: Nestlé | R4: Crema | S4: Entera | T4: Saco 25kg | U4: 25 | V4: =_xlfn.XLOOKUP(Tabla5[[#This Row],[Naturaleza]],Tabla37[Naturaleza],Tabla37[Código]) -> 01 | W4: =_xlfn.XLOOKUP(Tabla5[[#This Row],[Categoría]],Tabla1[Categoría],Tabla1[Código],"",0,1) -> 04 | X4: =_xlfn.XLOOKUP(Tabla5[[#This Row],[Tipo]],Tabla2[Tipo],Tabla2[Código],"",0,1) -> 01 | Y4: =_xlfn.XLOOKUP(Tabla5[[#This Row],[Formato]],Tabla3[Formato],Tabla3[Código],"",0,1) -> 02 | Z4: =_xlfn.XLOOKUP("Local",Tabla4[Mercado],Tabla4[Código],"",0,1) -> 01 | AA4: =_xlfn.XLOOKUP(Tabla5[[#This Row],[Cliente]],Tabla6[Cliente],Tabla6[Código]) -> 01 | AB4: =Tabla5[[#This Row],[Cód. Naturaleza]]&Tabla5[[#This Row],[Cód. Cliente]]&Tabla5[[#This Row],[Cód. Categoría]]&Tabla5[[#This Row],[Cód. Tipo]]&Tabla5[[#This Row],[Cód. Formato]]&Tabla5[[#This Row],[Cód. Mercado]] -> 010104010201 | AC4: Leche Entera Estándar 28% NE 25kg | AD4: 5002 | AE4: =IFERROR(IF(_xlfn.XLOOKUP(TEXT(Tabla5[[#This Row],[Cód. Patricio R.]],"0"),Diccionario!A:A,Diccionario!C:C,"",0,1)=0,"",_xlfn.XLOOKUP(TEXT(Tabla5[[#This Row],[Cód. Patricio R.]],"0"),Diccionario!A:A,Diccionario!C:C,"",0,1)),"") -> LEP NESTLÉ | AF4: 102
A5: Matequilla | B5: 05 | D5: Con sal | E5: 04 | M5: Cliente | N5: Código | P5: Servicio Terceros | Q5: Colun | R5: Leche en Polvo Instantanea | S5: Entera | T5: Saco 25kg | U5: 25 | V5: =_xlfn.XLOOKUP(Tabla5[[#This Row],[Naturaleza]],Tabla37[Naturaleza],Tabla37[Código]) -> 01 | W5: =_xlfn.XLOOKUP(Tabla5[[#This Row],[Categoría]],Tabla1[Categoría],Tabla1[Código],"",0,1) -> 10 | X5: =_xlfn.XLOOKUP(Tabla5[[#This Row],[Tipo]],Tabla2[Tipo],Tabla2[Código],"",0,1) -> 01 | Y5: =_xlfn.XLOOKUP(Tabla5[[#This Row],[Formato]],Tabla3[Formato],Tabla3[Código],"",0,1) -> 02 | Z5: =_xlfn.XLOOKUP("Local",Tabla4[Mercado],Tabla4[Código],"",0,1) -> 01 | AA5: =_xlfn.XLOOKUP(Tabla5[[#This Row],[Cliente]],Tabla6[Cliente],Tabla6[Código]) -> 02 | AB5: =Tabla5[[#This Row],[Cód. Naturaleza]]&Tabla5[[#This Row],[Cód. Cliente]]&Tabla5[[#This Row],[Cód. Categoría]]&Tabla5[[#This Row],[Cód. Tipo]]&Tabla5[[#This Row],[Cód. Formato]]&Tabla5[[#This Row],[Cód. Mercado]] -> 010210010201 | AC5: Leche Entera Instantánea 27% CN 25kg | AD5: 5003 | AE5: =IFERROR(IF(_xlfn.XLOOKUP(TEXT(Tabla5[[#This Row],[Cód. Patricio R.]],"0"),Diccionario!A:A,Diccionario!C:C,"",0,1)=0,"",_xlfn.XLOOKUP(TEXT(Tabla5[[#This Row],[Cód. Patricio R.]],"0"),Diccionario!A:A,Diccionario!C:C,"",0,1)),"") -> LEP COLUN | AF5: 103
A6: Materiales Diversos | B6: 06 | D6: Sin sal | E6: 05 | M6: Cliente no definido | N6: 00 | P6: Producto Propio | Q6: Cliente no definido | R6: Pre condensados | S6: Semidescremada | T6: Granel | V6: =_xlfn.XLOOKUP(Tabla5[[#This Row],[Naturaleza]],Tabla37[Naturaleza],Tabla37[Código]) -> 02 | W6: =_xlfn.XLOOKUP(Tabla5[[#This Row],[Categoría]],Tabla1[Categoría],Tabla1[Código],"",0,1) -> 03 | X6: =_xlfn.XLOOKUP(Tabla5[[#This Row],[Tipo]],Tabla2[Tipo],Tabla2[Código],"",0,1) -> 02 | Y6: =_xlfn.XLOOKUP(Tabla5[[#This Row],[Formato]],Tabla3[Formato],Tabla3[Código],"",0,1) -> 01 | Z6: =_xlfn.XLOOKUP("Local",Tabla4[Mercado],Tabla4[Código],"",0,1) -> 01 | AA6: =_xlfn.XLOOKUP(Tabla5[[#This Row],[Cliente]],Tabla6[Cliente],Tabla6[Código]) -> 00 | AB6: =Tabla5[[#This Row],[Cód. Naturaleza]]&Tabla5[[#This Row],[Cód. Cliente]]&Tabla5[[#This Row],[Cód. Categoría]]&Tabla5[[#This Row],[Cód. Tipo]]&Tabla5[[#This Row],[Cód. Formato]]&Tabla5[[#This Row],[Cód. Mercado]] -> 020003020101 | AC6: Precondensado SemiDescremado Rc0.201 Granel | AD6: 5004 | AE6: =IFERROR(IF(_xlfn.XLOOKUP(TEXT(Tabla5[[#This Row],[Cód. Patricio R.]],"0"),Diccionario!A:A,Diccionario!C:C,"",0,1)=0,"",_xlfn.XLOOKUP(TEXT(Tabla5[[#This Row],[Cód. Patricio R.]],"0"),Diccionario!A:A,Diccionario!C:C,"",0,1)),"") -> P. Descremado ST 45% | AF6: 104
A7: Leche Fresca Estandarizada | B7: 07 | D7: Sin especificar | E7: 06 | M7: Nestlé | N7: 01 | P7: Servicio Terceros | Q7: Nestlé | R7: Crema | S7: Entera | T7: Granel | V7: =_xlfn.XLOOKUP(Tabla5[[#This Row],[Naturaleza]],Tabla37[Naturaleza],Tabla37[Código]) -> 01 | W7: =_xlfn.XLOOKUP(Tabla5[[#This Row],[Categoría]],Tabla1[Categoría],Tabla1[Código],"",0,1) -> 04 | X7: =_xlfn.XLOOKUP(Tabla5[[#This Row],[Tipo]],Tabla2[Tipo],Tabla2[Código],"",0,1) -> 01 | Y7: =_xlfn.XLOOKUP(Tabla5[[#This Row],[Formato]],Tabla3[Formato],Tabla3[Código],"",0,1) -> 01 | Z7: =_xlfn.XLOOKUP("Local",Tabla4[Mercado],Tabla4[Código],"",0,1) -> 01 | AA7: =_xlfn.XLOOKUP(Tabla5[[#This Row],[Cliente]],Tabla6[Cliente],Tabla6[Código]) -> 01 | AB7: =Tabla5[[#This Row],[Cód. Naturaleza]]&Tabla5[[#This Row],[Cód. Cliente]]&Tabla5[[#This Row],[Cód. Categoría]]&Tabla5[[#This Row],[Cód. Tipo]]&Tabla5[[#This Row],[Cód. Formato]]&Tabla5[[#This Row],[Cód. Mercado]] -> 010104010101 | AC7: Crema fresca 42% Granel NE | AD7: 5005 | AE7: =IFERROR(IF(_xlfn.XLOOKUP(TEXT(Tabla5[[#This Row],[Cód. Patricio R.]],"0"),Diccionario!A:A,Diccionario!C:C,"",0,1)=0,"",_xlfn.XLOOKUP(TEXT(Tabla5[[#This Row],[Cód. Patricio R.]],"0"),Diccionario!A:A,Diccionario!C:C,"",0,1)),"") -> Crema 42% NESTLÉ | AF7: 105
A8: Suero | B8: 08 | D8: No definido | E8: 07 | M8: Colun | N8: 02 | P8: Producto Propio | Q8: Cliente no definido | R8: Crema | S8: Entera | T8: Granel | V8: =_xlfn.XLOOKUP(Tabla5[[#This Row],[Naturaleza]],Tabla37[Naturaleza],Tabla37[Código]) -> 02 | W8: =_xlfn.XLOOKUP(Tabla5[[#This Row],[Categoría]],Tabla1[Categoría],Tabla1[Código],"",0,1) -> 04 | X8: =_xlfn.XLOOKUP(Tabla5[[#This Row],[Tipo]],Tabla2[Tipo],Tabla2[Código],"",0,1) -> 01 | Y8: =_xlfn.XLOOKUP(Tabla5[[#This Row],[Formato]],Tabla3[Formato],Tabla3[Código],"",0,1) -> 01 | Z8: =_xlfn.XLOOKUP("Local",Tabla4[Mercado],Tabla4[Código],"",0,1) -> 01 | AA8: =_xlfn.XLOOKUP(Tabla5[[#This Row],[Cliente]],Tabla6[Cliente],Tabla6[Código]) -> 00 | AB8: =Tabla5[[#This Row],[Cód. Naturaleza]]&Tabla5[[#This Row],[Cód. Cliente]]&Tabla5[[#This Row],[Cód. Categoría]]&Tabla5[[#This Row],[Cód. Tipo]]&Tabla5[[#This Row],[Cód. Formato]]&Tabla5[[#This Row],[Cód. Mercado]] -> 020004010101 | AC8: Crema fresca 42% Granel CA | AD8: 5006 | AE8: =IFERROR(IF(_xlfn.XLOOKUP(TEXT(Tabla5[[#This Row],[Cód. Patricio R.]],"0"),Diccionario!A:A,Diccionario!C:C,"",0,1)=0,"",_xlfn.XLOOKUP(TEXT(Tabla5[[#This Row],[Cód. Patricio R.]],"0"),Diccionario!A:A,Diccionario!C:C,"",0,1)),"") -> Crema 42% CCAA | AF8: 106
A9: Extracto de Malta | B9: 09 | D9: Estandarizada | E9: 08 | M9: Soprole | N9: 03 | P9: Producto Propio | Q9: Cliente no definido | R9: Matequilla | S9: Sin sal | T9: Caja 20kg | U9: 20 | V9: =_xlfn.XLOOKUP(Tabla5[[#This Row],[Naturaleza]],Tabla37[Naturaleza],Tabla37[Código]) -> 02 | W9: =_xlfn.XLOOKUP(Tabla5[[#This Row],[Categoría]],Tabla1[Categoría],Tabla1[Código],"",0,1) -> 05 | X9: =_xlfn.XLOOKUP(Tabla5[[#This Row],[Tipo]],Tabla2[Tipo],Tabla2[Código],"",0,1) -> 05 | Y9: =_xlfn.XLOOKUP(Tabla5[[#This Row],[Formato]],Tabla3[Formato],Tabla3[Código],"",0,1) -> 03 | Z9: =_xlfn.XLOOKUP("Local",Tabla4[Mercado],Tabla4[Código],"",0,1) -> 01 | AA9: =_xlfn.XLOOKUP(Tabla5[[#This Row],[Cliente]],Tabla6[Cliente],Tabla6[Código]) -> 00 | AB9: =Tabla5[[#This Row],[Cód. Naturaleza]]&Tabla5[[#This Row],[Cód. Cliente]]&Tabla5[[#This Row],[Cód. Categoría]]&Tabla5[[#This Row],[Cód. Tipo]]&Tabla5[[#This Row],[Cód. Formato]]&Tabla5[[#This Row],[Cód. Mercado]] -> 020005050301 | AC9: Mantequilla S-sal 20kg | AD9: 6007 | AE9: =IFERROR(IF(_xlfn.XLOOKUP(TEXT(Tabla5[[#This Row],[Cód. Patricio R.]],"0"),Diccionario!A:A,Diccionario!C:C,"",0,1)=0,"",_xlfn.XLOOKUP(TEXT(Tabla5[[#This Row],[Cód. Patricio R.]],"0"),Diccionario!A:A,Diccionario!C:C,"",0,1)),"") -> Mantequilla sin Sal | AF9: 107
A10: Leche en Polvo Instantanea | B10: 10 | P10: Servicio Terceros | Q10: Soprole | R10: Leche en Polvo | S10: Entera | T10: Saco 25kg | U10: 25 | V10: =_xlfn.XLOOKUP(Tabla5[[#This Row],[Naturaleza]],Tabla37[Naturaleza],Tabla37[Código]) -> 01 | W10: =_xlfn.XLOOKUP(Tabla5[[#This Row],[Categoría]],Tabla1[Categoría],Tabla1[Código],"",0,1) -> 02 | X10: =_xlfn.XLOOKUP(Tabla5[[#This Row],[Tipo]],Tabla2[Tipo],Tabla2[Código],"",0,1) -> 01 | Y10: =_xlfn.XLOOKUP(Tabla5[[#This Row],[Formato]],Tabla3[Formato],Tabla3[Código],"",0,1) -> 02 | Z10: =_xlfn.XLOOKUP("Local",Tabla4[Mercado],Tabla4[Código],"",0,1) -> 01 | AA10: =_xlfn.XLOOKUP(Tabla5[[#This Row],[Cliente]],Tabla6[Cliente],Tabla6[Código]) -> 03 | AB10: =Tabla5[[#This Row],[Cód. Naturaleza]]&Tabla5[[#This Row],[Cód. Cliente]]&Tabla5[[#This Row],[Cód. Categoría]]&Tabla5[[#This Row],[Cód. Tipo]]&Tabla5[[#This Row],[Cód. Formato]]&Tabla5[[#This Row],[Cód. Mercado]] -> 010302010201 | AC10: Leche Entera Estándar 27% SP 25kg | AD10: 6008 | AE10: =IFERROR(IF(_xlfn.XLOOKUP(TEXT(Tabla5[[#This Row],[Cód. Patricio R.]],"0"),Diccionario!A:A,Diccionario!C:C,"",0,1)=0,"",_xlfn.XLOOKUP(TEXT(Tabla5[[#This Row],[Cód. Patricio R.]],"0"),Diccionario!A:A,Diccionario!C:C,"",0,1)),"") -> LEP | AF10: 108
A11: Leche en Polvo c/Lec | B11: 11 | P11: Servicio Terceros | Q11: Soprole | R11: Leche en Polvo | S11: Entera | T11: Saco 25kg | U11: 25 | V11: =_xlfn.XLOOKUP(Tabla5[[#This Row],[Naturaleza]],Tabla37[Naturaleza],Tabla37[Código]) -> 01 | W11: =_xlfn.XLOOKUP(Tabla5[[#This Row],[Categoría]],Tabla1[Categoría],Tabla1[Código],"",0,1) -> 02 | X11: =_xlfn.XLOOKUP(Tabla5[[#This Row],[Tipo]],Tabla2[Tipo],Tabla2[Código],"",0,1) -> 01 | Y11: =_xlfn.XLOOKUP(Tabla5[[#This Row],[Formato]],Tabla3[Formato],Tabla3[Código],"",0,1) -> 02 | Z11: =_xlfn.XLOOKUP("Local",Tabla4[Mercado],Tabla4[Código],"",0,1) -> 01 | AA11: =_xlfn.XLOOKUP(Tabla5[[#This Row],[Cliente]],Tabla6[Cliente],Tabla6[Código]) -> 03 | AB11: =Tabla5[[#This Row],[Cód. Naturaleza]]&Tabla5[[#This Row],[Cód. Cliente]]&Tabla5[[#This Row],[Cód. Categoría]]&Tabla5[[#This Row],[Cód. Tipo]]&Tabla5[[#This Row],[Cód. Formato]]&Tabla5[[#This Row],[Cód. Mercado]] -> 010302010201 | AC11: Leche Entera c/LdS 27% SP 25kg | AD11: 6009 | AE11: =IFERROR(IF(_xlfn.XLOOKUP(TEXT(Tabla5[[#This Row],[Cód. Patricio R.]],"0"),Diccionario!A:A,Diccionario!C:C,"",0,1)=0,"",_xlfn.XLOOKUP(TEXT(Tabla5[[#This Row],[Cód. Patricio R.]],"0"),Diccionario!A:A,Diccionario!C:C,"",0,1)),"") -> LEP c/Lec | AF11: 109
A12: Leche Fluida | B12: 12 | P12: Servicio Terceros | Q12: Soprole | R12: Leche en Polvo | S12: Descremada | T12: Saco 25kg | U12: 25 | V12: =_xlfn.XLOOKUP(Tabla5[[#This Row],[Naturaleza]],Tabla37[Naturaleza],Tabla37[Código]) -> 01 | W12: =_xlfn.XLOOKUP(Tabla5[[#This Row],[Categoría]],Tabla1[Categoría],Tabla1[Código],"",0,1) -> 02 | X12: =_xlfn.XLOOKUP(Tabla5[[#This Row],[Tipo]],Tabla2[Tipo],Tabla2[Código],"",0,1) -> 03 | Y12: =_xlfn.XLOOKUP(Tabla5[[#This Row],[Formato]],Tabla3[Formato],Tabla3[Código],"",0,1) -> 02 | Z12: =_xlfn.XLOOKUP("Local",Tabla4[Mercado],Tabla4[Código],"",0,1) -> 01 | AA12: =_xlfn.XLOOKUP(Tabla5[[#This Row],[Cliente]],Tabla6[Cliente],Tabla6[Código]) -> 03 | AB12: =Tabla5[[#This Row],[Cód. Naturaleza]]&Tabla5[[#This Row],[Cód. Cliente]]&Tabla5[[#This Row],[Cód. Categoría]]&Tabla5[[#This Row],[Cód. Tipo]]&Tabla5[[#This Row],[Cód. Formato]]&Tabla5[[#This Row],[Cód. Mercado]] -> 010302030201 | AC12: Leche Descremada MH SP 25kg | AD12: 6010 | AE12: =IFERROR(IF(_xlfn.XLOOKUP(TEXT(Tabla5[[#This Row],[Cód. Patricio R.]],"0"),Diccionario!A:A,Diccionario!C:C,"",0,1)=0,"",_xlfn.XLOOKUP(TEXT(Tabla5[[#This Row],[Cód. Patricio R.]],"0"),Diccionario!A:A,Diccionario!C:C,"",0,1)),"") -> Leche Descremada en Polvo | AF12: 110
P13: Servicio Terceros | Q13: Soprole | R13: Leche en Polvo | S13: Descremada | T13: Saco 25kg | U13: 25 | V13: =_xlfn.XLOOKUP(Tabla5[[#This Row],[Naturaleza]],Tabla37[Naturaleza],Tabla37[Código]) -> 01 | W13: =_xlfn.XLOOKUP(Tabla5[[#This Row],[Categoría]],Tabla1[Categoría],Tabla1[Código],"",0,1) -> 02 | X13: =_xlfn.XLOOKUP(Tabla5[[#This Row],[Tipo]],Tabla2[Tipo],Tabla2[Código],"",0,1) -> 03 | Y13: =_xlfn.XLOOKUP(Tabla5[[#This Row],[Formato]],Tabla3[Formato],Tabla3[Código],"",0,1) -> 02 | Z13: =_xlfn.XLOOKUP("Local",Tabla4[Mercado],Tabla4[Código],"",0,1) -> 01 | AA13: =_xlfn.XLOOKUP(Tabla5[[#This Row],[Cliente]],Tabla6[Cliente],Tabla6[Código]) -> 03 | AB13: =Tabla5[[#This Row],[Cód. Naturaleza]]&Tabla5[[#This Row],[Cód. Cliente]]&Tabla5[[#This Row],[Cód. Categoría]]&Tabla5[[#This Row],[Cód. Tipo]]&Tabla5[[#This Row],[Cód. Formato]]&Tabla5[[#This Row],[Cód. Mercado]] -> 010302030201 | AC13: Leche Descremada c/LdS MH SP 25kg | AD13: 6011 | AE13: =IFERROR(IF(_xlfn.XLOOKUP(TEXT(Tabla5[[#This Row],[Cód. Patricio R.]],"0"),Diccionario!A:A,Diccionario!C:C,"",0,1)=0,"",_xlfn.XLOOKUP(TEXT(Tabla5[[#This Row],[Cód. Patricio R.]],"0"),Diccionario!A:A,Diccionario!C:C,"",0,1)),"") -> Leche Descremada en Polvo C/Lec | AF13: 111
P14: Producto Propio | Q14: Cliente no definido | R14: Matequilla | S14: Con sal | T14: Caja 20kg | U14: 20 | V14: =_xlfn.XLOOKUP(Tabla5[[#This Row],[Naturaleza]],Tabla37[Naturaleza],Tabla37[Código]) -> 02 | W14: =_xlfn.XLOOKUP(Tabla5[[#This Row],[Categoría]],Tabla1[Categoría],Tabla1[Código],"",0,1) -> 05 | X14: =_xlfn.XLOOKUP(Tabla5[[#This Row],[Tipo]],Tabla2[Tipo],Tabla2[Código],"",0,1) -> 04 | Y14: =_xlfn.XLOOKUP(Tabla5[[#This Row],[Formato]],Tabla3[Formato],Tabla3[Código],"",0,1) -> 03 | Z14: =_xlfn.XLOOKUP("Local",Tabla4[Mercado],Tabla4[Código],"",0,1) -> 01 | AA14: =_xlfn.XLOOKUP(Tabla5[[#This Row],[Cliente]],Tabla6[Cliente],Tabla6[Código]) -> 00 | AB14: =Tabla5[[#This Row],[Cód. Naturaleza]]&Tabla5[[#This Row],[Cód. Cliente]]&Tabla5[[#This Row],[Cód. Categoría]]&Tabla5[[#This Row],[Cód. Tipo]]&Tabla5[[#This Row],[Cód. Formato]]&Tabla5[[#This Row],[Cód. Mercado]] -> 020005040301 | AC14: Mantequilla C-sal 20kg | AD14: 6012 | AE14: =IFERROR(IF(_xlfn.XLOOKUP(TEXT(Tabla5[[#This Row],[Cód. Patricio R.]],"0"),Diccionario!A:A,Diccionario!C:C,"",0,1)=0,"",_xlfn.XLOOKUP(TEXT(Tabla5[[#This Row],[Cód. Patricio R.]],"0"),Diccionario!A:A,Diccionario!C:C,"",0,1)),"") | AF14: 112
P15: Servicio Terceros | Q15: Colun | R15: Suero | S15: Descremada | T15: Saco 25kg | U15: 25 | V15: =_xlfn.XLOOKUP(Tabla5[[#This Row],[Naturaleza]],Tabla37[Naturaleza],Tabla37[Código]) -> 01 | W15: =_xlfn.XLOOKUP(Tabla5[[#This Row],[Categoría]],Tabla1[Categoría],Tabla1[Código],"",0,1) -> 08 | X15: =_xlfn.XLOOKUP(Tabla5[[#This Row],[Tipo]],Tabla2[Tipo],Tabla2[Código],"",0,1) -> 03 | Y15: =_xlfn.XLOOKUP(Tabla5[[#This Row],[Formato]],Tabla3[Formato],Tabla3[Código],"",0,1) -> 02 | Z15: =_xlfn.XLOOKUP("Local",Tabla4[Mercado],Tabla4[Código],"",0,1) -> 01 | AA15: =_xlfn.XLOOKUP(Tabla5[[#This Row],[Cliente]],Tabla6[Cliente],Tabla6[Código]) -> 02 | AB15: =Tabla5[[#This Row],[Cód. Naturaleza]]&Tabla5[[#This Row],[Cód. Cliente]]&Tabla5[[#This Row],[Cód. Categoría]]&Tabla5[[#This Row],[Cód. Tipo]]&Tabla5[[#This Row],[Cód. Formato]]&Tabla5[[#This Row],[Cód. Mercado]] -> 010208030201 | AC15: Suero WPC CN 25kg | AD15: 6013 | AE15: =IFERROR(IF(_xlfn.XLOOKUP(TEXT(Tabla5[[#This Row],[Cód. Patricio R.]],"0"),Diccionario!A:A,Diccionario!C:C,"",0,1)=0,"",_xlfn.XLOOKUP(TEXT(Tabla5[[#This Row],[Cód. Patricio R.]],"0"),Diccionario!A:A,Diccionario!C:C,"",0,1)),"") -> Suero en Polvo Colun | AF15: 113
P16: Servicio Terceros | Q16: Nestlé | R16: Extracto de Malta | S16: Entera | T16: Saco 25kg | U16: 25 | V16: =_xlfn.XLOOKUP(Tabla5[[#This Row],[Naturaleza]],Tabla37[Naturaleza],Tabla37[Código]) -> 01 | W16: =_xlfn.XLOOKUP(Tabla5[[#This Row],[Categoría]],Tabla1[Categoría],Tabla1[Código],"",0,1) -> 09 | X16: =_xlfn.XLOOKUP(Tabla5[[#This Row],[Tipo]],Tabla2[Tipo],Tabla2[Código],"",0,1) -> 01 | Y16: =_xlfn.XLOOKUP(Tabla5[[#This Row],[Formato]],Tabla3[Formato],Tabla3[Código],"",0,1) -> 02 | Z16: =_xlfn.XLOOKUP("Local",Tabla4[Mercado],Tabla4[Código],"",0,1) -> 01 | AA16: =_xlfn.XLOOKUP(Tabla5[[#This Row],[Cliente]],Tabla6[Cliente],Tabla6[Código]) -> 01 | AB16: =Tabla5[[#This Row],[Cód. Naturaleza]]&Tabla5[[#This Row],[Cód. Cliente]]&Tabla5[[#This Row],[Cód. Categoría]]&Tabla5[[#This Row],[Cód. Tipo]]&Tabla5[[#This Row],[Cód. Formato]]&Tabla5[[#This Row],[Cód. Mercado]] -> 010109010201 | AC16: PROTOMALT NE 25kg | AD16: 6014 | AE16: =IFERROR(IF(_xlfn.XLOOKUP(TEXT(Tabla5[[#This Row],[Cód. Patricio R.]],"0"),Diccionario!A:A,Diccionario!C:C,"",0,1)=0,"",_xlfn.XLOOKUP(TEXT(Tabla5[[#This Row],[Cód. Patricio R.]],"0"),Diccionario!A:A,Diccionario!C:C,"",0,1)),"") | AF16: 114
P17: Servicio Terceros | Q17: Soprole | R17: Leche en Polvo | S17: Entera | T17: Saco 25kg | U17: 25 | V17: =_xlfn.XLOOKUP(Tabla5[[#This Row],[Naturaleza]],Tabla37[Naturaleza],Tabla37[Código]) -> 01 | W17: =_xlfn.XLOOKUP(Tabla5[[#This Row],[Categoría]],Tabla1[Categoría],Tabla1[Código],"",0,1) -> 02 | X17: =_xlfn.XLOOKUP(Tabla5[[#This Row],[Tipo]],Tabla2[Tipo],Tabla2[Código],"",0,1) -> 01 | Y17: =_xlfn.XLOOKUP(Tabla5[[#This Row],[Formato]],Tabla3[Formato],Tabla3[Código],"",0,1) -> 02 | Z17: =_xlfn.XLOOKUP("Local",Tabla4[Mercado],Tabla4[Código],"",0,1) -> 01 | AA17: =_xlfn.XLOOKUP(Tabla5[[#This Row],[Cliente]],Tabla6[Cliente],Tabla6[Código]) -> 03 | AB17: =Tabla5[[#This Row],[Cód. Naturaleza]]&Tabla5[[#This Row],[Cód. Cliente]]&Tabla5[[#This Row],[Cód. Categoría]]&Tabla5[[#This Row],[Cód. Tipo]]&Tabla5[[#This Row],[Cód. Formato]]&Tabla5[[#This Row],[Cód. Mercado]] -> 010302010201 | AC17: Leche Entera en Polvo Regular 25kg | AD17: 7001 | AE17: =IFERROR(IF(_xlfn.XLOOKUP(TEXT(Tabla5[[#This Row],[Cód. Patricio R.]],"0"),Diccionario!A:A,Diccionario!C:C,"",0,1)=0,"",_xlfn.XLOOKUP(TEXT(Tabla5[[#This Row],[Cód. Patricio R.]],"0"),Diccionario!A:A,Diccionario!C:C,"",0,1)),"") | AF17: 115
P18: Servicio Terceros | Q18: Soprole | R18: Leche en Polvo Instantanea | S18: Entera | T18: Saco 25kg | U18: 25 | V18: =_xlfn.XLOOKUP(Tabla5[[#This Row],[Naturaleza]],Tabla37[Naturaleza],Tabla37[Código]) -> 01 | W18: =_xlfn.XLOOKUP(Tabla5[[#This Row],[Categoría]],Tabla1[Categoría],Tabla1[Código],"",0,1) -> 10 | X18: =_xlfn.XLOOKUP(Tabla5[[#This Row],[Tipo]],Tabla2[Tipo],Tabla2[Código],"",0,1) -> 01 | Y18: =_xlfn.XLOOKUP(Tabla5[[#This Row],[Formato]],Tabla3[Formato],Tabla3[Código],"",0,1) -> 02 | Z18: =_xlfn.XLOOKUP("Local",Tabla4[Mercado],Tabla4[Código],"",0,1) -> 01 | AA18: =_xlfn.XLOOKUP(Tabla5[[#This Row],[Cliente]],Tabla6[Cliente],Tabla6[Código]) -> 03 | AB18: =Tabla5[[#This Row],[Cód. Naturaleza]]&Tabla5[[#This Row],[Cód. Cliente]]&Tabla5[[#This Row],[Cód. Categoría]]&Tabla5[[#This Row],[Cód. Tipo]]&Tabla5[[#This Row],[Cód. Formato]]&Tabla5[[#This Row],[Cód. Mercado]] -> 010310010201 | AC18: Leche Entera en Polvo Instantánea 25kg | AD18: 7002 | AE18: =IFERROR(IF(_xlfn.XLOOKUP(TEXT(Tabla5[[#This Row],[Cód. Patricio R.]],"0"),Diccionario!A:A,Diccionario!C:C,"",0,1)=0,"",_xlfn.XLOOKUP(TEXT(Tabla5[[#This Row],[Cód. Patricio R.]],"0"),Diccionario!A:A,Diccionario!C:C,"",0,1)),"") | AF18: 116
P19: Servicio Terceros | Q19: Soprole | R19: Leche en Polvo | S19: Descremada | T19: Saco 25kg | U19: 25 | V19: =_xlfn.XLOOKUP(Tabla5[[#This Row],[Naturaleza]],Tabla37[Naturaleza],Tabla37[Código]) -> 01 | W19: =_xlfn.XLOOKUP(Tabla5[[#This Row],[Categoría]],Tabla1[Categoría],Tabla1[Código],"",0,1) -> 02 | X19: =_xlfn.XLOOKUP(Tabla5[[#This Row],[Tipo]],Tabla2[Tipo],Tabla2[Código],"",0,1) -> 03 | Y19: =_xlfn.XLOOKUP(Tabla5[[#This Row],[Formato]],Tabla3[Formato],Tabla3[Código],"",0,1) -> 02 | Z19: =_xlfn.XLOOKUP("Local",Tabla4[Mercado],Tabla4[Código],"",0,1) -> 01 | AA19: =_xlfn.XLOOKUP(Tabla5[[#This Row],[Cliente]],Tabla6[Cliente],Tabla6[Código]) -> 03 | AB19: =Tabla5[[#This Row],[Cód. Naturaleza]]&Tabla5[[#This Row],[Cód. Cliente]]&Tabla5[[#This Row],[Cód. Categoría]]&Tabla5[[#This Row],[Cód. Tipo]]&Tabla5[[#This Row],[Cód. Formato]]&Tabla5[[#This Row],[Cód. Mercado]] -> 010302030201 | AC19: Leche en Polvo Descremada Regular 25kg | AD19: 7003 | AE19: =IFERROR(IF(_xlfn.XLOOKUP(TEXT(Tabla5[[#This Row],[Cód. Patricio R.]],"0"),Diccionario!A:A,Diccionario!C:C,"",0,1)=0,"",_xlfn.XLOOKUP(TEXT(Tabla5[[#This Row],[Cód. Patricio R.]],"0"),Diccionario!A:A,Diccionario!C:C,"",0,1)),"") | AF19: 117
P20: Servicio Terceros | Q20: Soprole | R20: Leche en Polvo Instantanea | S20: Descremada | T20: Saco 25kg | U20: 25 | V20: =_xlfn.XLOOKUP(Tabla5[[#This Row],[Naturaleza]],Tabla37[Naturaleza],Tabla37[Código]) -> 01 | W20: =_xlfn.XLOOKUP(Tabla5[[#This Row],[Categoría]],Tabla1[Categoría],Tabla1[Código],"",0,1) -> 10 | X20: =_xlfn.XLOOKUP(Tabla5[[#This Row],[Tipo]],Tabla2[Tipo],Tabla2[Código],"",0,1) -> 03 | Y20: =_xlfn.XLOOKUP(Tabla5[[#This Row],[Formato]],Tabla3[Formato],Tabla3[Código],"",0,1) -> 02 | Z20: =_xlfn.XLOOKUP("Local",Tabla4[Mercado],Tabla4[Código],"",0,1) -> 01 | AA20: =_xlfn.XLOOKUP(Tabla5[[#This Row],[Cliente]],Tabla6[Cliente],Tabla6[Código]) -> 03 | AB20: =Tabla5[[#This Row],[Cód. Naturaleza]]&Tabla5[[#This Row],[Cód. Cliente]]&Tabla5[[#This Row],[Cód. Categoría]]&Tabla5[[#This Row],[Cód. Tipo]]&Tabla5[[#This Row],[Cód. Formato]]&Tabla5[[#This Row],[Cód. Mercado]] -> 010310030201 | AC20: Leche en Polvo Descremada Instantánea 25kg | AD20: 7004 | AE20: =IFERROR(IF(_xlfn.XLOOKUP(TEXT(Tabla5[[#This Row],[Cód. Patricio R.]],"0"),Diccionario!A:A,Diccionario!C:C,"",0,1)=0,"",_xlfn.XLOOKUP(TEXT(Tabla5[[#This Row],[Cód. Patricio R.]],"0"),Diccionario!A:A,Diccionario!C:C,"",0,1)),"") | AF20: 118
P21: Producto Propio | Q21: Cliente no definido | R21: Materiales diversos | S21: No definido | T21: Saco 25kg | V21: =_xlfn.XLOOKUP(Tabla5[[#This Row],[Naturaleza]],Tabla37[Naturaleza],Tabla37[Código]) -> 02 | W21: =_xlfn.XLOOKUP(Tabla5[[#This Row],[Categoría]],Tabla1[Categoría],Tabla1[Código],"",0,1) -> 06 | X21: =_xlfn.XLOOKUP(Tabla5[[#This Row],[Tipo]],Tabla2[Tipo],Tabla2[Código],"",0,1) -> 07 | Y21: =_xlfn.XLOOKUP(Tabla5[[#This Row],[Formato]],Tabla3[Formato],Tabla3[Código],"",0,1) -> 02 | Z21: =_xlfn.XLOOKUP("Local",Tabla4[Mercado],Tabla4[Código],"",0,1) -> 01 | AA21: =_xlfn.XLOOKUP(Tabla5[[#This Row],[Cliente]],Tabla6[Cliente],Tabla6[Código]) -> 00 | AB21: =Tabla5[[#This Row],[Cód. Naturaleza]]&Tabla5[[#This Row],[Cód. Cliente]]&Tabla5[[#This Row],[Cód. Categoría]]&Tabla5[[#This Row],[Cód. Tipo]]&Tabla5[[#This Row],[Cód. Formato]]&Tabla5[[#This Row],[Cód. Mercado]] -> 020006070201 | AC21: Rework | AE21: =IFERROR(IF(_xlfn.XLOOKUP(TEXT(Tabla5[[#This Row],[Cód. Patricio R.]],"0"),Diccionario!A:A,Diccionario!C:C,"",0,1)=0,"",_xlfn.XLOOKUP(TEXT(Tabla5[[#This Row],[Cód. Patricio R.]],"0"),Diccionario!A:A,Diccionario!C:C,"",0,1)),"") | AF21: 119
P22: Producto Propio | Q22: Cliente no definido | R22: Pre condensados | S22: Semidescremada | T22: Granel | V22: =_xlfn.XLOOKUP(Tabla5[[#This Row],[Naturaleza]],Tabla37[Naturaleza],Tabla37[Código]) -> 02 | W22: =_xlfn.XLOOKUP(Tabla5[[#This Row],[Categoría]],Tabla1[Categoría],Tabla1[Código],"",0,1) -> 03 | X22: =_xlfn.XLOOKUP(Tabla5[[#This Row],[Tipo]],Tabla2[Tipo],Tabla2[Código],"",0,1) -> 02 | Y22: =_xlfn.XLOOKUP(Tabla5[[#This Row],[Formato]],Tabla3[Formato],Tabla3[Código],"",0,1) -> 01 | Z22: =_xlfn.XLOOKUP("Local",Tabla4[Mercado],Tabla4[Código],"",0,1) -> 01 | AA22: =_xlfn.XLOOKUP(Tabla5[[#This Row],[Cliente]],Tabla6[Cliente],Tabla6[Código]) -> 00 | AB22: =Tabla5[[#This Row],[Cód. Naturaleza]]&Tabla5[[#This Row],[Cód. Cliente]]&Tabla5[[#This Row],[Cód. Categoría]]&Tabla5[[#This Row],[Cód. Tipo]]&Tabla5[[#This Row],[Cód. Formato]]&Tabla5[[#This Row],[Cód. Mercado]] -> 020003020101 | AC22: P. Semidescremado ST 45% CCAA | AE22: P. Semidescremado ST 45% CCAA | AF22: 120
P23: Servicio Terceros | Q23: Nestlé | R23: Pre condensados | S23: Semidescremada | T23: Granel | V23: =_xlfn.XLOOKUP(Tabla5[[#This Row],[Naturaleza]],Tabla37[Naturaleza],Tabla37[Código]) -> 01 | W23: =_xlfn.XLOOKUP(Tabla5[[#This Row],[Categoría]],Tabla1[Categoría],Tabla1[Código],"",0,1) -> 03 | X23: =_xlfn.XLOOKUP(Tabla5[[#This Row],[Tipo]],Tabla2[Tipo],Tabla2[Código],"",0,1) -> 02 | Y23: =_xlfn.XLOOKUP(Tabla5[[#This Row],[Formato]],Tabla3[Formato],Tabla3[Código],"",0,1) -> 01 | Z23: =_xlfn.XLOOKUP("Local",Tabla4[Mercado],Tabla4[Código],"",0,1) -> 01 | AA23: =_xlfn.XLOOKUP(Tabla5[[#This Row],[Cliente]],Tabla6[Cliente],Tabla6[Código]) -> 01 | AB23: =Tabla5[[#This Row],[Cód. Naturaleza]]&Tabla5[[#This Row],[Cód. Cliente]]&Tabla5[[#This Row],[Cód. Categoría]]&Tabla5[[#This Row],[Cód. Tipo]]&Tabla5[[#This Row],[Cód. Formato]]&Tabla5[[#This Row],[Cód. Mercado]] -> 010103020101 | AC23: P. Semidescremado ST 45% | AE23: P. Semidescremado ST 45% | AF23: 121
P24: Servicio Terceros | Q24: Soprole | R24: Leche en Polvo c/Lec | S24: Descremada | T24: Saco 25kg | V24: =_xlfn.XLOOKUP(Tabla5[[#This Row],[Naturaleza]],Tabla37[Naturaleza],Tabla37[Código]) -> 01 | W24: =_xlfn.XLOOKUP(Tabla5[[#This Row],[Categoría]],Tabla1[Categoría],Tabla1[Código],"",0,1) -> 11 | X24: =_xlfn.XLOOKUP(Tabla5[[#This Row],[Tipo]],Tabla2[Tipo],Tabla2[Código],"",0,1) -> 03 | Y24: =_xlfn.XLOOKUP(Tabla5[[#This Row],[Formato]],Tabla3[Formato],Tabla3[Código],"",0,1) -> 02 | Z24: =_xlfn.XLOOKUP("Local",Tabla4[Mercado],Tabla4[Código],"",0,1) -> 01 | AA24: =_xlfn.XLOOKUP(Tabla5[[#This Row],[Cliente]],Tabla6[Cliente],Tabla6[Código]) -> 03 | AB24: =Tabla5[[#This Row],[Cód. Naturaleza]]&Tabla5[[#This Row],[Cód. Cliente]]&Tabla5[[#This Row],[Cód. Categoría]]&Tabla5[[#This Row],[Cód. Tipo]]&Tabla5[[#This Row],[Cód. Formato]]&Tabla5[[#This Row],[Cód. Mercado]] -> 010311030201 | AC24: Leche Descremada en Polvo c/Lec | AE24: Leche Descremada en Polvo c/Lec | AF24: 122
P25: Producto Propio | Q25: Cliente no definido | R25: Leche Fluida | S25: Estandarizada | T25: Granel | V25: =_xlfn.XLOOKUP(Tabla5[[#This Row],[Naturaleza]],Tabla37[Naturaleza],Tabla37[Código]) -> 02 | W25: =_xlfn.XLOOKUP(Tabla5[[#This Row],[Categoría]],Tabla1[Categoría],Tabla1[Código],"",0,1) -> 12 | X25: =_xlfn.XLOOKUP(Tabla5[[#This Row],[Tipo]],Tabla2[Tipo],Tabla2[Código],"",0,1) -> 08 | Y25: =_xlfn.XLOOKUP(Tabla5[[#This Row],[Formato]],Tabla3[Formato],Tabla3[Código],"",0,1) -> 01 | Z25: =_xlfn.XLOOKUP("Local",Tabla4[Mercado],Tabla4[Código],"",0,1) -> 01 | AA25: =_xlfn.XLOOKUP(Tabla5[[#This Row],[Cliente]],Tabla6[Cliente],Tabla6[Código]) -> 00 | AB25: =Tabla5[[#This Row],[Cód. Naturaleza]]&Tabla5[[#This Row],[Cód. Cliente]]&Tabla5[[#This Row],[Cód. Categoría]]&Tabla5[[#This Row],[Cód. Tipo]]&Tabla5[[#This Row],[Cód. Formato]]&Tabla5[[#This Row],[Cód. Mercado]] -> 020012080101 | AC25: Leche estandarizada | AE25: Leche estandarizada | AF25: 123

Sheet Recetas (detalle)
A1: Código | B1: Material | C1: Componente | D1: Unidad | E1: Cantidad / 100 kg
A2: 5001 | B2: Precondensado Entero NE Granel | C2: Sólidos Grasos | D2: kg | E2: 15
C3: Sólidos No Grasos | D3: kg | E3: 33
A4: 5002 | B4: Leche Entera Estándar 28% NE 25kg | C4: Sólidos Grasos | D4: kg | E4: 28
C5: Sólidos No Grasos | D5: kg | E5: 68.5
C6: Saco de papel | D6: un | E6: 4
C7: Bolsa Film CE | D7: kg | E7: 0.6
A8: 5003 | B8: Leche Entera Instantánea 27% CN 25kg | C8: Sólidos Grasos | D8: kg | E8: 27
C9: Sólidos No Grasos | D9: kg | E9: 69.2
C10: Lecitina de soya | D10: kg | E10: 0.3
C11: Saco de papel | D11: un | E11: 4
C12: Bolsa Film CE | D12: kg | E12: 0.6
A13: 5004 | B13: Precondensado SemiDescremado Rc0.201 Granel | C13: Sólidos Grasos | D13: kg | E13: 7.55
C14: Sólidos No Grasos | D14: kg | E14: 37.45
A15: 5005 | B15: Crema fresca 42% Granel NE | C15: Sólidos Grasos | D15: kg | E15: 42
C16: Sólidos No Grasos | D16: kg | E16: 5
A17: 5006 | B17: Crema fresca 42% Granel CA | C17: Sólidos Grasos | D17: kg | E17: 42
C18: Sólidos No Grasos | D18: kg | E18: 5
A19: 6007 | B19: Mantequilla S-sal 20kg | C19: Sólidos Grasos | D19: kg | E19: 84
C20: Sólidos No Grasos | D20: kg | E20: 2
C21: Caja cartón K | D21: un | E21: 5
C22: Bolsa PEBD | D22: un | E22: 5
A23: 6008 | B23: Leche Entera Estándar 27% SP 25kg | C23: Sólidos Grasos | D23: kg | E23: 27
C24: Sólidos No Grasos | D24: kg | E24: 69.5
C25: Saco de papel | D25: un | E25: 4
C26: Bolsa Film CE | D26: kg | E26: 0.6
A27: 6009 | B27: Leche Entera c/LdS 27% SP 25kg | C27: Sólidos Grasos | D27: kg | E27: 27
C28: Sólidos No Grasos | D28: kg | E28: 69.2
C29: Lecitina de soya | D29: kg | E29: 0.3
C30: Saco de papel | D30: un | E30: 4
C31: Bolsa Film CE | D31: kg | E31: 0.6
A32: 6010 | B32: Leche Descremada MH SP 25kg | C32: Sólidos Grasos | D32: kg | E32: 1.5
C33: Sólidos No Grasos | D33: kg | E33: 94.5
C34: Saco de papel | D34: un | E34: 4
C35: Bolsa Film CE | D35: kg | E35: 0.6
A36: 6011 | B36: Leche Descremada c/LdS MH SP 25kg | C36: Sólidos Grasos | D36: kg | E36: 1.5
C37: Sólidos No Grasos | D37: kg | E37: 94.2
C38: Lecitina de soya | D38: kg | E38: 0.3
C39: Saco de papel | D39: un | E39: 4
C40: Bolsa Film CE | D40: kg | E40: 0.6
...

Sheet Resumen por receta
A1: Código | B1: Material | C1: Sólidos Grasos (kg) | D1: Sólidos No Grasos (kg) | E1: Saco de papel (un) | F1: Bolsa Film CE (kg) | G1: Lecitina de soya (kg) | H1: Caja cartón K (un) | I1: Bolsa PEBD (un) | J1: Sal Fina (kg) | K1: Sólidos Disueltos (kg)
A2: 5001 | B2: Precondensado Entero NE Granel | C2: 15 | D2: 33
A3: 5002 | B3: Leche Entera Estándar 28% NE 25kg | C3: 28 | D3: 68.5 | E3: 4 | F3: 0.6
A4: 5003 | B4: Leche Entera Instantánea 27% CN 25kg | C4: 27 | D4: 69.2 | E4: 4 | F4: 0.6 | G4: 0.3
A5: 5004 | B5: Precondensado SemiDescremado Rc0.201 Granel | C5: 7.55 | D5: 37.45
A6: 5005 | B6: Crema fresca 42% Granel NE | C6: 42 | D6: 5
A7: 5006 | B7: Crema fresca 42% Granel CA | C7: 42 | D7: 5
A8: 6007 | B8: Mantequilla S-sal 20kg | C8: 84 | D8: 2 | H8: 5 | I8: 5
A9: 6008 | B9: Leche Entera Estándar 27% SP 25kg | C9: 27 | D9: 69.5 | E9: 4 | F9: 0.6
A10: 6009 | B10: Leche Entera c/LdS 27% SP 25kg | C10: 27 | D10: 69.2 | E10: 4 | F10: 0.6 | G10: 0.3
A11: 6010 | B11: Leche Descremada MH SP 25kg | C11: 1.5 | D11: 94.5 | E11: 4 | F11: 0.6
A12: 6011 | B12: Leche Descremada c/LdS MH SP 25kg | C12: 1.5 | D12: 94.2 | E12: 4 | F12: 0.6 | G12: 0.3
A13: 6012 | B13: Mantequilla C-sal 20kg | C13: 84 | D13: 1.85 | H13: 5 | I13: 5 | J13: 0.15
A14: 6013 | B14: Suero WPC CN 25kg | C14: 5 | D14: 91 | E14: 4 | F14: 0.6
A15: 6014 | B15: PROTOMALT NE 25kg | E15: 4 | F15: 0.6 | K15: 96.5

Sheet Diccionario
A1: Código | B1: Material | C1: Nombre Producción | D1: Nombre asignación Leche
A2: 5001 | B2: Precondensado Entero NE Granel | C2: P. Entero ST 48%
A3: 5002 | B3: Leche Entera Estándar 28% NE 25kg | C3: LEP NESTLÉ
A4: 5003 | B4: Leche Entera Instantánea 27% CN 25kg | C4: LEP COLUN
A5: 5004 | B5: Precondensado SemiDescremado Rc0.201 Granel | C5: P. Descremado ST 45%
A6: 5005 | B6: Crema fresca 42% Granel NE | C6: Crema 42% NESTLÉ
A7: 5006 | B7: Crema fresca 42% Granel CA | C7: Crema 42% CCAA
A8: 6007 | B8: Mantequilla S-sal 20kg | C8: Mantequilla sin Sal
A9: 6008 | B9: Leche Entera Estándar 27% SP 25kg | C9: LEP
A10: 6009 | B10: Leche Entera c/LdS 27% SP 25kg | C10: LEP c/Lec
A11: 6010 | B11: Leche Descremada MH SP 25kg | C11: Leche Descremada en Polvo
A12: 6011 | B12: Leche Descremada c/LdS MH SP 25kg | C12: Leche Descremada en Polvo C/Lec
A13: 6012 | B13: Mantequilla C-sal 20kg
A14: 6013 | B14: Suero WPC CN 25kg | C14: Suero en Polvo Colun
A15: 6014 | B15: PROTOMALT NE 25kg
C21: Cat | D21: Tipo producto | E21: Formato | F21: Servicio/Producto | G21: Local/Export
B22: Categoria Prod | C22: N1 | D22: N2
B23: Leche en Polvo | C23: 01
B24: Pre condensados | C24: 02
B25: Crema | C25: 03
B26: Matequilla | C26: 04
B27: Materiales Diversos | C27: 05
B28: Leche Fresca Estandarizada | C28: 06
